Workbook

Sheet Raw_Export
A1: MidCore Industries Pvt Ltd - Budget vs Actuals RAW EXTRACT (UNPROCESSED)
A2: Extracted: 07-Aug-2026 14:41 IST | Source systems: SAP + Excel manual + legacy | Confidential
A4: Month / Period | B4: Fin Year | C4: Qtr | D4: Catgory | E4: LineItem | F4: Budget Amt | G4: Actual Amt | H4: Comments / Assumptions | I4: Flag | J4: Origin | K4: Notes2
A5: Jan-23 | C5: Q4 | D5: Cost | E5: HR | F5: 14.0 | G5: 13.5 | H5: Salaries + benefits + attrition replacement; slight overrun from mid-year hiring | I5: flag | J5: user_upload
A6: February 2024 | B6: FY24 | C6: q4 | D6: Revenue | E6: Product B | F6: 6160000 | H6: Legacy product line; declining due to market share loss; budgeted conservatively | J6: csv_import | K6: duplicate?
A7: Feb-24 | B7: FY24 | C7: Q4 | D7: Cost | E7: Finance & Admin | F7: 8.8 | G7: 8.8 | H7: Compliance, audit, office admin; tightly controlled; near-budget historically | I7: 1 | J7: legacy_system
A8: Aug-23 | B8: FY24 | C8: Q2 | D8: Cost | E8: Markting | F8: 18 | G8: 19.98 | H8: Brand + digital spends; FY24 overrun due to new product launch campaign | I8: check | J8: SAP_dump_v2
A9: Mar-24 | B9: FY24 | C9: Q4 | D9: Cost | E9: Finance & Admin | F9: Rs. 7.7 | G9: 7.85 L | H9: Compliance, audit, office admin; tightly controlled; near-budget historically | I9: flag | J9: export_apr.xlsx
A10: Mar-23 | B10: 23 | C10: Q4 | D10: Expenses | E10: Operations | F10: Rs. 78.75 | G10: 84.26 | H10: Manufacturing + COGS + overhead; 45% of revenue; input cost inflation trend FY24 | I10: 0 | J10: csv_import | K10: duplicate?
A11: Jun 23 | B11: FY24 | C11: Q1 | D11: Revenue | E11: Services | F11: 42 | G11: 46.2 | H11: After-sales and maintenance contracts; growing segment; sticky recurring revenue | I11: 0 | J11: export_apr.xlsx | K11: duplicate?
A12: 2024-01 | B12: FY24 | C12: Q4 | D12: Cost | E12: sales | F12: 24.75 | G12: 2525000 | H12: Field sales team + incentive payouts; ~10% of revenue; stable cost base | I12: 1 | J12: user_upload | K12: verify this
A13: Mar-23 | B13: FY23 | C13: Q4 | D13: Cost | E13: Finance & Admin | F13: 7.0 | G13: Rs. 7.14 | H13: Compliance, audit, office admin; tightly controlled; near-budget historically | I13: 1 | J13: csv_import
A14: Jul-22 | B14: FY23 | C14: Q2 | D14: Cost | E14: Finance & Admin | F14: 8.00 L | G14: 8.16 | H14: Compliance, audit, office admin; tightly controlled; near-budget historically | I14: 1 | J14: csv_import | K14: verify this
A15: SEP-22 | B15: FY23 | C15: Quarter 2 | D15: Revenue | E15: Services | F15: 40 | G15: 43,2 | H15: After-sales and maintenance contracts; growing segment; sticky recurring revenue | J15: manual_entry
A16: Feb-24 | B16: FY24 | C16: Q4 | D16: Cost | E16: Marketting | F16: 18 | G16: 19.8 | H16: BRAND + DIGITAL SPENDS; FY24 OVERRUN DUE TO NEW PRODUCT LAUNCH CAMPAIGN | I16: 1 | J16: legacy_system
A17: Nov-23 | B17: N/A | C17: Qtr 3 | D17: COST | E17: People | F17: 18.15 | G17: 19.24 | H17: Salaries + benefits + attrition replacement; slight overrun from mid-year hiring | I17: 0 | J17: SAP_dump_v2
A18: Jun-22 | B18: FY23 | C18: Q1 | D18: Cost | E18: hr | F18: 10.5 | G18: 10.71 lakhs | H18: Salaries + benefits + attrition replacement; slight overrun from mid-year hiring | I18: check | J18: manual_entry | K18: old value
A19: Jun-22 | B19: FY23 | C19: Q1 | D19: Cst | E19: Operations | F19: 78.75 | G19: ₹80.33 | H19: Manufacturing + COGS + overhead; 45% of revenue; input cost inflation trend FY24 | J19: SAP_dump_v2
A20: Jan-23 | B20: FY23 | C20: Q4 | D20: Revnue | E20: product a | F20: 1.1250e+02 | G20: 117 | H20: Core manufactured product; 50% revenue share; seasonal Q3 peak (festive demand) | I20: x | J20: SAP_dump_v2 | K20: reconcile
A21: Jun-22 | B21: FY23 | C21: Q1 | D21: Exp | E21: Sales | F21: 17.5 | G21: 17.85 | H21: Field sales team + incentive payouts; ~10% of revenue; stable cost base | I21: 0
A22: Oct-22 | B22: FY23 | C22: Q3 | D22: COST | E22: Sls | F22: 25.0 lakhs | G22: 25.75 | H22: Field sales team + incentive payouts; ~10% of revenue; stable cost base | I22: 0 | J22: csv_import | K22: verify this
A23: Oct-23 | B23: FY24 | C23: Q3 | D23: Cost | E23: Sales | F23: 27.5 | G23: 28.32 | H23: Field sales team + incentive payouts; ~10% of revenue; stable cost base | I23: 1 | K23: old value
A24: Jan-24 | B24: FY24 | C24: Q4 | D24: Rev | E24: product a | F24: 124.2 | G24: Rs. 130.41 | H24: CORE MANUFACTURED PRODUCT; 50% REVENUE SHARE; SEASONAL Q3 PEAK (FESTIVE DEMAND) | I24: x | J24: user_upload | K24: duplicate?
A25: Jul-23 | B25: FY24 | C25: Q2 | D25: Revenue | E25: Product A | F25: 11040000 | G25: 113.71 L | H25: Core manufactured product; 50% revenue share; seasonal Q3 peak (festive demand)
A26: Mar/24 | B26: FY24 | C26: Q4 | D26: Revenue | E26: Product B | F26: 53.9 | G26: 44.2 | H26: Legacy product line; declining due to market [truncated] | I26: x | K26: duplicate?
A27: Apr-22 | B27: FY23 | C27: Quarter 1 | D27: Cost | E27: Sales | F27: 0.0001 | G27: ₹17.68 | H27: Field sales team + incentive payouts; ... | I27: x | K27: ??
A28: 2023-05 | B28: FY24 | C28: Q1 | D28: Exp | E28: Sales | F28: 19.25 | G28: 19.06 | H28: Field sales team + incentive payouts; ... | I28: x | J28: user_upload | K28: reconcile
A29: Nov-23 | B29: Financial Year 24 | C29: Q3 | D29: Cost | E29: Finance/Admin | F29: Rs. 12.1 | G29: 12.34 | H29: Compliance, audit, office admin; tightly controlled; near-budget historically | I29: 1 | J29: csv_import
A30: 2022-06 | B30: FY23 | C30: Q1 | D30: Cost | E30: Brand | F30: 14 | G30: 14.56 | H30: Brand + digital spends; FY24 overrun due to new product launch campaign | I30: OK | J30: SAP_dump_v2 | K30: old value
A31: Mar-23 | B31: 23 | C31: Q4 | D31: Expenses | E31: Operations | F31: Rs. 78.75 | G31: 84.26 | H31: Manufacturing + COGS + overhead; 45% o... | I31: flag | J31: csv_import | K31: duplicate?
A32: Jan/24 | B32: FY 24 | C32: Q4 | D32: Cost | E32: OPERATIONS | F32: 108.9 | H32: Manufacturing + COGS + overhead; 45% of revenue; input cost inflation trend FY24 | I32: 1 | J32: manual_entry
A33: Dec/23 | B33: FY24 | C33: Q3 | D33: Revenue | E33: Product A | F33: 138 | G33: 143.52 | H33: Core manufactured product; 50% revenue share; seasonal Q3 peak (festive demand) | I33: 0 | J33: csv_import | K33: old value
A34: Jul-22 | C34: q2 | D34: Income | E34: Product A | F34: 100 | G34: 102 | H34: Core manufactured product; 50% revenue share; seasonal Q3 peak (festive demand) | J34: export_apr.xlsx | K34: duplicate?
A35: Jul 23 | B35: FY24 | C35: Q2 | D35: Cost | E35: Finance & Admin | F35: 8.8 | G35: 8.98 | H35: COMPLIANCE, AUDIT, OFFICE ADMIN; TIGHTLY CONTROLLED; NEAR-BUDGET HISTORICALLY | I35: flag | J35: manual_entry
A36: Oct-22 | B36: FY 23 | C36: Q3 | D36: Cost | E36: Marketing | F36: 20 | G36: ₹20.40 | H36: Brand + digital spends; FY24 overrun due to new product launch campaign | I36: 0 | J36: csv_import | K36: reconcile
A37: Feb-24 | B37: FY24 | C37: Q4 | D37: Costs | E37: HR | F37: 13.2 | G37: 13.73 | H37: Salaries + benefits + attrition replac... | I37: flag
A38: 3/1/2024 | B38: FY24 | C38: Q4 | D38: Cost | E38: People | F38: 11.55 | G38: Rs. 12.24 | H38: Salaries + benefits + attrition replac... | I38: 0 | J38: user_upload
A39: Mar-24 | B39: FY24 | C39: Q4 | D39: Rev | E39: Svc | F39: 42 | G39: 47.88 | H39: After-sales and maintenance contracts; growing segment; sticky recurring revenue | I39: x | J39: legacy_system
A40: Dec-23 | B40: FY24 | C40: Q3 | D40: Cst | E40: Manufacturing | F40: 121 | G40: 130.68 | H40: Manufacturing + COGS + overhead; 45% of revenue; input cost inflation trend FY24 | J40: manual_entry | K40: ??
A41: May-22 | B41: FY23 | C41: Q1 | D41: Revnue | E41: Services | F41: 35 | G41: 36.75 | H41: After-sales and maintenance contracts;... | J41: user_upload | K41: verify this
...

Sheet Raw_Export_Clean
A1: MidCore Industries Pvt Ltd — Budget vs Actual Data (FY2023–FY2024)
A2: Unit: ₹ Lakhs | Source: Synthetic dataset modelled on Indian mid-market manufacturing benchmarks
A3: Month | B3: FY | C3: Quarter | D3: Category | E3: Line Item | F3: Budget Reqired (₹ L) | G3: Actual Budget (₹ L) | H3: Assumption Note
A4: Apr-22 | B4: FY23 | C4: Q1 | D4: Revenue | E4: Product A | F4: 87.5 | G4: 89.25 | H4: Core manufactured product; 50% revenue share; seasonal Q3 peak (festive demand)
A5: Apr-22 | B5: FY23 | C5: Q1 | D5: Revenue | E5: Product B | F5: 52.5 | G5: 50.4 | H5: Legacy product line; declining due to market share loss; budgeted conservatively
A6: Apr-22 | B6: FY23 | C6: Q1 | D6: Revenue | E6: Services | F6: 35 | G6: 36.4 | H6: After-sales and maintenance contracts; growing segment; sticky recurring revenue
A7: Apr-22 | B7: FY23 | C7: Q1 | D7: Cost | E7: Operations | F7: 78.75 | G7: 80.33 | H7: Manufacturing + COGS + overhead; 45% of revenue; input cost inflation trend FY24
A8: Apr-22 | B8: FY23 | C8: Q1 | D8: Cost | E8: Sales | F8: 17.5 | G8: 17.68 | H8: Field sales team + incentive payouts; ~10% of revenue; stable cost base
A9: Apr-22 | B9: FY23 | C9: Q1 | D9: Cost | E9: Marketing | F9: 14 | G9: 14.42 | H9: Brand + digital spends; FY24 overrun due to new product launch campaign
A10: Apr-22 | B10: FY23 | C10: Q1 | D10: Cost | E10: HR | F10: 10.5 | G10: 10.71 | H10: Salaries + benefits + attrition replacement; slight overrun from mid-year hiring
A11: Apr-22 | B11: FY23 | C11: Q1 | D11: Cost | E11: Finance & Admin | F11: 7 | G11: 7.07 | H11: Compliance, audit, office admin; tightly controlled; near-budget historically
A12: May-22 | B12: FY23 | C12: Q1 | D12: Revenue | E12: Product A | F12: 87.5 | G12: 88.38 | H12: Core manufactured product; 50% revenue share; seasonal Q3 peak (festive demand)
A13: May-22 | B13: FY23 | C13: Q1 | D13: Revenue | E13: Product B | F13: 52.5 | G13: 49.88 | H13: Legacy product line; declining due to market share loss; budgeted conservatively
A14: May-22 | B14: FY23 | C14: Q1 | D14: Revenue | E14: Services | F14: 35 | G14: 36.75 | H14: After-sales and maintenance contracts; growing segment; sticky recurring revenue
A15: May-22 | B15: FY23 | C15: Q1 | D15: Cost | E15: Operations | F15: 78.75 | G15: 81.11 | H15: Manufacturing + COGS + overhead; 45% of revenue; input cost inflation trend FY24
... A195: Mar-24 | B195: FY24 | C195: Q4 | D195: Cost | E195: Finance & Admin | F195: 7.7 | G195: 7.85 | H195: Compliance, audit, office admin; tightly controlled; near-budget historically

Sheet Raw_Export_Cleaned
A1: Month | B1: FY | C1: Quarter | D1: Category | E1: Line Item | F1: Budget (₹ L) | G1: Actual (₹ L) | H1: Comments / Assumptions
A2: Apr-22 | B2: FY23 | C2: Q1 | D2: Cost | E2: HR | F2: 10.5 | G2: 10.71 | H2: Salaries + benefits + attrition replacement; slight overrun from mid-year hiring
A3: Apr-22 | B3: FY23 | C3: Q1 | D3: Cost | E3: Operations | F3: 78.75 | G3: 80.33 | H3: Manufacturing + COGS + overhead; 45% of revenue; input cost inflation trend FY24
A4: Apr-22 | B4: FY23 | C4: Q1 | D4: Revenue | E4: Product B | F4: 52.5 | G4: 50.4 | H4: LEGACY PRODUCT LINE; DECLINING DUE TO MARKET SHARE LOSS; BUDGETED CONSERVATIVELY
A5: Apr-22 | B5: FY23 | C5: Q1 | D5: Revenue | E5: Product A | F5: 87.5 | G5: 89.25 | H5: Core manufactured product; 50% revenue share; seasonal Q3 peak (festive demand)
A6: Apr-22 | B6: FY23 | C6: Q1 | D6: Cost | E6: Marketing | F6: 14 | G6: 14.42 | H6: Brand + digital spends; FY24 overrun due to new product launch campaign
A7: Apr-22 | B7: FY23 | C7: Q1 | D7: Revenue | E7: Services | F7: 35 | G7: 36.4 | H7: After-sales and maintenance contracts; growing segment; sticky recurring revenue
A8: Apr-22 | B8: FY23 | C8: Q1 | D8: Cost | E8: Finance & Admin | G8: 7.07 | H8: Compliance, audit, office admin; tightly controlled; near-budget historically
A9: Apr-22 | B9: FY23 | C9: Q1 | D9: Cost | E9: Sales | F9: 0.0001 | G9: 17.68 | H9: Field sales team + incentive payouts; ...
A10: Aug-22 | B10: FY23 | C10: Q2 | D10: Cost | E10: HR | F10: 12 | G10: 12.36 | H10: Salaries + benefits + attrition replacement; slight overrun from mid-year hiring
A11: Aug-22 | B11: FY23 | C11: Q2 | D11: Cost | E11: Operations | F11: 90 | G11: 92.7 | H11: Manufacturing + COGS + overhead; 45% of revenue; input cost inflation trend FY24
A12: Aug-22 | B12: FY23 | C12: Q2 | D12: Revenue | E12: Product A | F12: 100 | G12: 101 | H12: Core manufactured product; 50% revenue...
A13: Aug-22 | B13: FY23 | C13: Q2 | D13: Revenue | E13: Services | F13: 40 | G13: 42.4 | H13: After-sales and maintenance contracts; growing segment; sticky recurring revenue
A14: Aug-22 | B14: FY23 | C14: Q2 | D14: Cost | E14: Sales | F14: 20 | G14: 19.6 | H14: Field sales team + incentive payouts; ~10% of revenue; stable cost base
A15: Aug-22 | B15: FY23 | C15: Q2 | D15: Cost | E15: Marketing | F15: 16 | G15: 16.8 | H15: Brand + digital spends; FY24 overrun d...
A16: Aug-22 | B16: FY23 | C16: Q2 | D16: Revenue | E16: Product B | F16: 60 | G16: 55.8 | H16: Legacy product line; declining due to market share loss; budgeted conservatively
A17: Aug-22 | B17: FY23 | C17: Q2 | D17: Cost | E17: Finance & Admin | F17: 8 | H17: Compliance, audit, office admin; tightly controlled; near-budget historically
A18: Dec-22 | B18: FY23 | C18: Q3 | D18: Cost | E18: Operations | F18: 112.5 | G18: 118.12 | H18: Manufacturing + COGS + overhead; 45% of revenue; input cost inflation trend FY24
A19: Dec-22 | B19: FY23 | C19: Q3 | D19: Revenue | E19: Services | F19: 50 | G19: 54 | H19: After-sales and maintenance contracts; growing segment; sticky recurring revenue
A20: Dec-22 | B20: FY23 | C20: Q3 | D20: Cost | E20: HR | F20: 15 | G20: 15.45 | H20: Salaries + benefits + attrition replacement; slight overrun from mid-year hiring
A21: Dec-22 | B21: FY23 | C21: Q3 | D21: Revenue | E21: Product A | F21: 125 | G21: 128.75 | H21: Core manufactured product; 50% revenue...
A22: Dec-22 | B22: FY23 | C22: Q3 | D22: Cost | E22: Finance & Admin | F22: 10.1 | G22: 10 | H22: Compliance, audit, office admin; tightly controlled; near-budget historically
A23: Dec-22 | B23: FY23 | C23: Q3 | D23: Cost | E23: Sales | F23: 25 | H23: Field sales team + incentive payouts; ~10% of revenue; stable cost base
A24: Dec-22 | B24: FY23 | C24: Q3 | D24: Revenue | E24: Product B | G24: 68.25 | H24: Legacy product line; declining due to market share loss; budgeted conservatively
A25: Dec-22 | B25: FY23 | C25: Q3 | D25: Cost | E25: Marketing | G25: 21 | H25: Brand + digital spends; FY24 overrun due to new product launch campaign
A26: Feb-23 | B26: FY23 | C26: Q4 | D26: Cost | E26: Finance & Admin | F26: 8 | G26: 8 | H26: Compliance, audit, office admin; tightly controlled; near-budget historically
A27: Feb-23 | B27: FY23 | C27: Q4 | D27: Cost | E27: HR | F27: 12 | G27: 12.36 | H27: Salaries + benefits + attrition replacement; slight overrun from mid-year hiring
A28: Feb-23 | B28: FY23 | C28: Q4 | D28: Cost | E28: Sales | F28: 20 | G28: 20.2 | H28: FIELD SALES TEAM + INCENTIVE PAYOUTS; ~10% OF REVENUE; STABLE COST BASE
A29: Feb-23 | B29: FY23 | C29: Q4 | D29: Cost | E29: Operations | F29: 90 | G29: 94.5 | H29: Manufacturing + COGS + overhead; 45% of revenue; input cost inflation trend FY24
A30: Feb-23 | B30: FY23 | C30: Q4 | D30: Revenue | E30: Product B | F30: 60 | G30: 54 | H30: Legacy product line; declining due to market share loss; budgeted conservatively
A31: Feb-23 | B31: FY23 | C31: Q4 | D31: Cost | E31: Marketing | F31: 16 | G31: 16.48 | H31: Brand + digital spends; FY24 overrun due to new product launch campaign
A32: Feb-23 | B32: FY23 | C32: Q4 | D32: Revenue | E32: Product A | G32: 103 | H32: Core manufactured product; 50% revenue share; seasonal Q3 peak (festive demand)
A33: Feb-23 | B33: FY23 | C33: Q4 | D33: Revenue | E33: Services | F33: 40 | H33: After-sales and maintenance contracts; growing segment; sticky recurring revenue
A34: Jan-23 | B34: FY23 | C34: Q4 | D34: Cost | E34: HR | F34: 14 | G34: 13.5 | H34: Salaries + benefits + attrition replacement; slight overrun from mid-year hiring
A35: Jan-23 | B35: FY23 | C35: Q4 | D35: Revenue | E35: Services | F35: 45 | G35: 49.05 | H35: After-sales and maintenance contracts; growing segment; sticky recurring revenue
A36: Jan-23 | B36: FY23 | C36: Q4 | D36: Revenue | E36: Product B | F36: 67.5 | G36: 62.1 | H36: Legacy product line; declining due to market share loss; budgeted conservatively
A37: Jan-23 | B37: FY23 | C37: Q4 | D37: Cost | E37: Operations | F37: 101.25 | G37: 107.33 | H37: Manufacturing + COGS + overhead; 45% of revenue; input cost inflation trend FY24
A38: Jan-23 | B38: FY23 | C38: Q4 | D38: Revenue | E38: Product A | F38: 112.5 | G38: 117 | H38: Core manufactured product; 50% revenue share; seasonal Q3 peak (festive demand)
A39: Jan-23 | B39: FY23 | C39: Q4 | D39: Cost | E39: Finance & Admin | F39: 9 | G39: 9.09 | H39: Compliance, audit, office admin; tightly controlled; near-budget historically
A40: Jan-23 | B40: FY23 | C40: Q4 | D40: Cost | E40: Marketing | F40: 18 | G40: 18.72 | H40: Brand + digital spends; FY24 overrun due to new product launch campaign
...

Sheet Variance Engine
A1: MidCore Industries Pvt Ltd — Variance Analysis Engine
A2: Formulas pull from Data sheet | Green = favourable | Amber = watch | Red = adverse
A3: Month | B3: FY | C3: Quarter | D3: Category | E3: Line Item | F3: Budget Reqired (₹ L) | G3: Actual Budget (₹ L) | H3: Abs Variance (₹ L) | I3: % Variance | J3: RAG Status | K3: YTD Cumulative Variance (₹ L)
A4: =Raw_Export_Clean!A4 -> Apr-22 | B4: =Raw_Export_Clean!B4 -> FY23 | C4: =Raw_Export_Clean!C4 -> Q1 | D4: =Raw_Export_Clean!D4 -> Revenue | E4: =Raw_Export_Clean!E4 -> Product A | F4: =Raw_Export_Clean!F4 -> 87.5 | G4: =Raw_Export_Clean!G4 -> 89.25 | H4: =G4-F4 -> 1.75 | I4: =IF(F4<>0,(G4-F4)/F4,0) -> 0.02 | J4: =IF(D4="Revenue",IF(I4>=0.02,"GREEN",IF(I4>=-0.05,"AMBER","RED")),IF(I4<=-0.02,"GREEN",IF(I4<=0.05,"AMBER","RED"))) -> GREEN | K4: =SUMPRODUCT((B$4:B4=B4)*(E$4:E4=E4)*H$4:H4) -> 1.75
A5: =Raw_Export_Clean!A5 -> Apr-22 | B5: =Raw_Export_Clean!B5 -> FY23 | C5: =Raw_Export_Clean!C5 -> Q1 | D5: =Raw_Export_Clean!D5 -> Revenue | E5: =Raw_Export_Clean!E5 -> Product B | F5: =Raw_Export_Clean!F5 -> 52.5 | G5: =Raw_Export_Clean!G5 -> 50.4 | H5: =G5-F5 -> -2.1 | I5: =IF(F5<>0,(G5-F5)/F5,0) -> -0.04 | J5: =IF(D5="Revenue",IF(I5>=0.02,"GREEN",IF(I5>=-0.05,"AMBER","RED")),IF(I5<=-0.02,"GREEN",IF(I5<=0.05,"AMBER","RED"))) -> AMBER | K5: =SUMPRODUCT((B$4:B5=B5)*(E$4:E5=E5)*H$4:H5) -> -2.1
A6: =Raw_Export_Clean!A6 -> Apr-22 | B6: =Raw_Export_Clean!B6 -> FY23 | C6: =Raw_Export_Clean!C6 -> Q1 | D6: =Raw_Export_Clean!D6 -> Revenue | E6: =Raw_Export_Clean!E6 -> Services | F6: =Raw_Export_Clean!F6 -> 35 | G6: =Raw_Export_Clean!G6 -> 36.4 | H6: =G6-F6 -> 1.4 | I6: =IF(F6<>0,(G6-F6)/F6,0) -> 0.04 | J6: =IF(D6="Revenue",IF(I6>=0.02,"GREEN",IF(I6>=-0.05,"AMBER","RED")),IF(I6<=-0.02,"GREEN",IF(I6<=0.05,"AMBER","RED"))) -> GREEN | K6: =SUMPRODUCT((B$4:B6=B6)*(E$4:E6=E6)*H$4:H6) -> 1.4
A7: =Raw_Export_Clean!A7 -> Apr-22 | B7: =Raw_Export_Clean!B7 -> FY23 | C7: =Raw_Export_Clean!C7 -> Q1 | D7: =Raw_Export_Clean!D7 -> Cost | E7: =Raw_Export_Clean!E7 -> Operations | F7: =Raw_Export_Clean!F7 -> 78.75 | G7: =Raw_Export_Clean!G7 -> 80.33 | H7: =G7-F7 -> 1.58 | I7: =IF(F7<>0,(G7-F7)/F7,0) -> 0.020063492 | J7: =IF(D7="Revenue",IF(I7>=0.02,"GREEN",IF(I7>=-0.05,"AMBER","RED")),IF(I7<=-0.02,"GREEN",IF(I7<=0.05,"AMBER","RED"))) -> AMBER | K7: =SUMPRODUCT((B$4:B7=B7)*(E$4:E7=E7)*H$4:H7) -> 1.58
A8: =Raw_Export_Clean!A8 -> Apr-22 | B8: =Raw_Export_Clean!B8 -> FY23 | C8: =Raw_Export_Clean!C8 -> Q1 | D8: =Raw_Export_Clean!D8 -> Cost | E8: =Raw_Export_Clean!E8 -> Sales | F8: =Raw_Export_Clean!F8 -> 17.5 | G8: =Raw_Export_Clean!G8 -> 17.68 | H8: =G8-F8 -> 0.18 | I8: =IF(F8<>0,(G8-F8)/F8,0) -> 0.010285714 | J8: =IF(D8="Revenue",IF(I8>=0.02,"GREEN",IF(I8>=-0.05,"AMBER","RED")),IF(I8<=-0.02,"GREEN",IF(I8<=0.05,"AMBER","RED"))) -> AMBER | K8: =SUMPRODUCT((B$4:B8=B8)*(E$4:E8=E8)*H$4:H8) -> 0.18
A9: =Raw_Export_Clean!A9 -> Apr-22 | B9: =Raw_Export_Clean!B9 -> FY23 | C9: =Raw_Export_Clean!C9 -> Q1 | D9: =Raw_Export_Clean!D9 -> Cost | E9: =Raw_Export_Clean!E9 -> Marketing | F9: =Raw_Export_Clean!F9 -> 14 | G9: =Raw_Export_Clean!G9 -> 14.42 | H9: =G9-F9 -> 0.42 | I9: =IF(F9<>0,(G9-F9)/F9,0) -> 0.03 | J9: =IF(D9="Revenue",IF(I9>=0.02,"GREEN",IF(I9>=-0.05,"AMBER","RED")),IF(I9<=-0.02,"GREEN",IF(I9<=0.05,"AMBER","RED"))) -> AMBER | K9: =SUMPRODUCT((B$4:B9=B9)*(E$4:E9=E9)*H$4:H9) -> 0.42
A10: =Raw_Export_Clean!A10 -> Apr-22 | B10: =Raw_Export_Clean!B10 -> FY23 | C10: =Raw_Export_Clean!C10 -> Q1 | D10: =Raw_Export_Clean!D10 -> Cost | E10: =Raw_Export_Clean!E10 -> HR | F10: =Raw_Export_Clean!F10 -> 10.5 | G10: =Raw_Export_Clean!G10 -> 10.71 | H10: =G10-F10 -> 0.21 | I10: =IF(F10<>0,(G10-F10)/F10,0) -> 0.02 | J10: =IF(D10="Revenue",IF(I10>=0.02,"GREEN",IF(I10>=-0.05,"AMBER","RED")),IF(I10<=-0.02,"GREEN",IF(I10<=0.05,"AMBER","RED"))) -> AMBER | K10: =SUMPRODUCT((B$4:B10=B10)*(E$4:E10=E10)*H$4:H10) -> 0.21
A11: =Raw_Export_Clean!A11 -> Apr-22 | B11: =Raw_Export_Clean!B11 -> FY23 | C11: =Raw_Export_Clean!C11 -> Q1 | D11: =Raw_Export_Clean!D11 -> Cost | E11: =Raw_Export_Clean!E11 -> Finance & Admin | F11: =Raw_Export_Clean!F11 -> 7 | G11: =Raw_Export_Clean!G11 -> 7.07 | H11: =G11-F11 -> 0.07 | I11: =IF(F11<>0,(G11-F11)/F11,0) -> 0.01 | J11: =IF(D11="Revenue",IF(I11>=0.02,"GREEN",IF(I11>=-0.05,"AMBER","RED")),IF(I11<=-0.02,"GREEN",IF(I11<=0.05,"AMBER","RED"))) -> AMBER | K11: =SUMPRODUCT((B$4:B11=B11)*(E$4:E11=E11)*H$4:H11) -> 0.07
A12: =Raw_Export_Clean!A12 -> May-22 | B12: =Raw_Export_Clean!B12 -> FY23 | C12: =Raw_Export_Clean!C12 -> Q1 | D12: =Raw_Export_Clean!D12 -> Revenue | E12: =Raw_Export_Clean!E12 -> Product A | F12: =Raw_Export_Clean!F12 -> 87.5 | G12: =Raw_Export_Clean!G12 -> 88.38 | H12: =G12-F12 -> 0.88 | I12: =IF(F12<>0,(G12-F12)/F12,0) -> 0.010057143 | J12: =IF(D12="Revenue",IF(I12>=0.02,"GREEN",IF(I12>=-0.05,"AMBER","RED")),IF(I12<=-0.02,"GREEN",IF(I12<=0.05,"AMBER","RED"))) -> AMBER | K12: =SUMPRODUCT((B$4:B12=B12)*(E$4:E12=E12)*H$4:H12) -> 2.63
A13: =Raw_Export_Clean!A13 -> May-22 | B13: =Raw_Export_Clean!B13 -> FY23 | C13: =Raw_Export_Clean!C13 -> Q1 | D13: =Raw_Export_Clean!D13 -> Revenue | E13: =Raw_Export_Clean!E13 -> Product B | F13: =Raw_Export_Clean!F13 -> 52.5 | G13: =Raw_Export_Clean!G13 -> 49.88 | H13: =G13-F13 -> -2.62 | I13: =IF(F13<>0,(G13-F13)/F13,0) -> -0.049904762 | J13: =IF(D13="Revenue",IF(I13>=0.02,"GREEN",IF(I13>=-0.05,"AMBER","RED")),IF(I13<=-0.02,"GREEN",IF(I13<=0.05,"AMBER","RED"))) -> AMBER | K13: =SUMPRODUCT((B$4:B13=B13)*(E$4:E13=E13)*H$4:H13) -> -4.72
A14: =Raw_Export_Clean!A14 -> May-22 | B14: =Raw_Export_Clean!B14 -> FY23 | C14: =Raw_Export_Clean!C14 -> Q1 | D14: =Raw_Export_Clean!D14 -> Revenue | E14: =Raw_Export_Clean!E14 -> Services | F14: =Raw_Export_Clean!F14 -> 35 | G14: =Raw_Export_Clean!G14 -> 36.75 | H14: =G14-F14 -> 1.75 | I14: =IF(F14<>0,(G14-F14)/F14,0) -> 0.05 | J14: =IF(D14="Revenue",IF(I14>=0.02,"GREEN",IF(I14>=-0.05,"AMBER","RED")),IF(I14<=-0.02,"GREEN",IF(I14<=0.05,"AMBER","RED"))) -> GREEN | K14: =SUMPRODUCT((B$4:B14=B14)*(E$4:E14=E14)*H$4:H14) -> 3.15
A15: =Raw_Export_Clean!A15 -> May-22 | B15: =Raw_Export_Clean!B15 -> FY23 | C15: =Raw_Export_Clean!C15 -> Q1 | D15: =Raw_Export_Clean!D15 -> Cost | E15: =Raw_Export_Clean!E15 -> Operations | F15: =Raw_Export_Clean!F15 -> 78.75 | G15: =Raw_Export_Clean!G15 -> 81.11 | H15: =G15-F15 -> 2.36 | I15: =IF(F15<>0,(G15-F15)/F15,0) -> 0.029968254 | J15: =IF(D15="Revenue",IF(I15>=0.02,"GREEN",IF(I15>=-0.05,"AMBER","RED")),IF(I15<=-0.02,"GREEN",IF(I15<=0.05,"AMBER","RED"))) -> AMBER | K15: =SUMPRODUCT((B$4:B15=B15)*(E$4:E15=E15)*H$4:H15) -> 3.94
... A195: =Raw_Export_Clean!A195 -> Mar-24 | B195: =Raw_Export_Clean!B195 -> FY24 | C195: =Raw_Export_Clean!C195 -> Q4 | D195: =Raw_Export_Clean!D195 -> Cost | E195: =Raw_Export_Clean!E195 -> Finance & Admin | F195: =Raw_Export_Clean!F195 -> 7.7 | G195: =Raw_Export_Clean!G195 -> 7.85 | H195: =G195-F195 -> 0.15 | I195: =IF(F195<>0,(G195-F195)/F195,0) -> 0.019480519 | J195: =IF(D195="Revenue",IF(I195>=0.02,"GREEN",IF(I195>=-0.05,"AMBER","RED")),IF(I195<=-0.02,"GREEN",IF(I195<=0.05,"AMBER","RED"))) -> AMBER | K195: =SUMPRODUCT((B$4:B195=B195)*(E$4:E195=E195)*H$4:H195) -> 1.14

Sheet Scenario Analysis
A1: MidCore Industries Pvt Ltd — Scenario & Sensitivity Analysis
A2: Stress-tests FY24 P&L under revenue shortfall and cost overrun scenarios | Unit: ₹ Lakhs
A3: This sheet will contain: Two-variable sensitivity table | Scenario Manager (Base / Moderate Stress / Severe Stress)
A4: SECTION 1: FY24 BASE P&L SUMMARY
A5: Line Item | B5: Category | C5: Budget Reqired (₹ L) | D5: Actual Budget (₹ L) | E5: Abs Variance (₹ L) | F5: % Variance
A6: Product A | B6: Revenue | C6: =SUMPRODUCT((Raw_Export_Clean!$B$4:$B$195="FY24")*(Raw_Export_Clean!$E$4:$E$195="Product A")*Raw_Export_Clean!$F$4:$F$195) -> 1380 | D6: =SUMPRODUCT((Raw_Export_Clean!$B$4:$B$195="FY24")*(Raw_Export_Clean!$E$4:$E$195="Product A")*Raw_Export_Clean!$G$4:$G$195) -> 1436.59 | E6: =D6-C6 -> 56.59 | F6: =IF(C6<>0,(D6-C6)/C6,0) -> 0.041007246
A7: Product B | B7: Revenue | C7: =SUMPRODUCT((Raw_Export_Clean!$B$4:$B$195="FY24")*(Raw_Export_Clean!$E$4:$E$195="Product B")*Raw_Export_Clean!$F$4:$F$195) -> 770 | D7: =SUMPRODUCT((Raw_Export_Clean!$B$4:$B$195="FY24")*(Raw_Export_Clean!$E$4:$E$195="Product B")*Raw_Export_Clean!$G$4:$G$195) -> 667.43 | E7: =D7-C7 -> -102.57 | F7: =IF(C7<>0,(D7-C7)/C7,0) -> -0.13320779
A8: Services | B8: Revenue | C8: =SUMPRODUCT((Raw_Export_Clean!$B$4:$B$195="FY24")*(Raw_Export_Clean!$E$4:$E$195="Services")*Raw_Export_Clean!$F$4:$F$195) -> 600 | D8: =SUMPRODUCT((Raw_Export_Clean!$B$4:$B$195="FY24")*(Raw_Export_Clean!$E$4:$E$195="Services")*Raw_Export_Clean!$G$4:$G$195) -> 668.16 | E8: =D8-C8 -> 68.16 | F8: =IF(C8<>0,(D8-C8)/C8,0) -> 0.1136
A9: Operations | B9: Cost | C9: =SUMPRODUCT((Raw_Export_Clean!$B$4:$B$195="FY24")*(Raw_Export_Clean!$E$4:$E$195="Operations")*Raw_Export_Clean!$F$4:$F$195) -> 1210 | D9: =SUMPRODUCT((Raw_Export_Clean!$B$4:$B$195="FY24")*(Raw_Export_Clean!$E$4:$E$195="Operations")*Raw_Export_Clean!$G$4:$G$195) -> 1300.03 | E9: =D9-C9 -> 90.03 | F9: =IF(C9<>0,(D9-C9)/C9,0) -> 0.074404959
A10: Sales | B10: Cost | C10: =SUMPRODUCT((Raw_Export_Clean!$B$4:$B$195="FY24")*(Raw_Export_Clean!$E$4:$E$195="Sales")*Raw_Export_Clean!$F$4:$F$195) -> 275 | D10: =SUMPRODUCT((Raw_Export_Clean!$B$4:$B$195="FY24")*(Raw_Export_Clean!$E$4:$E$195="Sales")*Raw_Export_Clean!$G$4:$G$195) -> 278.07 | E10: =D10-C10 -> 3.07 | F10: =IF(C10<>0,(D10-C10)/C10,0) -> 0.011163636
A11: Marketing | B11: Cost | C11: =SUMPRODUCT((Raw_Export_Clean!$B$4:$B$195="FY24")*(Raw_Export_Clean!$E$4:$E$195="Marketing")*Raw_Export_Clean!$F$4:$F$195) -> 225 | D11: =SUMPRODUCT((Raw_Export_Clean!$B$4:$B$195="FY24")*(Raw_Export_Clean!$E$4:$E$195="Marketing")*Raw_Export_Clean!$G$4:$G$195) -> 248.25 | E11: =D11-C11 -> 23.25 | F11: =IF(C11<>0,(D11-C11)/C11,0) -> 0.10333333
A12: HR | B12: Cost | C12: =SUMPRODUCT((Raw_Export_Clean!$B$4:$B$195="FY24")*(Raw_Export_Clean!$E$4:$E$195="HR")*Raw_Export_Clean!$F$4:$F$195) -> 165 | D12: =SUMPRODUCT((Raw_Export_Clean!$B$4:$B$195="FY24")*(Raw_Export_Clean!$E$4:$E$195="HR")*Raw_Export_Clean!$G$4:$G$195) -> 172.41 | E12: =D12-C12 -> 7.41 | F12: =IF(C12<>0,(D12-C12)/C12,0) -> 0.044909091
A13: Finance & Admin | B13: Cost | C13: =SUMPRODUCT((Raw_Export_Clean!$B$4:$B$195="FY24")*(Raw_Export_Clean!$E$4:$E$195="Finance & Admin")*Raw_Export_Clean!$F$4:$F$195) -> 110 | D13: =SUMPRODUCT((Raw_Export_Clean!$B$4:$B$195="FY24")*(Raw_Export_Clean!$E$4:$E$195="Finance & Admin")*Raw_Export_Clean!$G$4:$G$195) -> 111.14 | E13: =D13-C13 -> 1.14 | F13: =IF(C13<>0,(D13-C13)/C13,0) -> 0.010363636
A14: Total Revenue | C14: =SUM(C6:C8) -> 2750 | D14: =SUM(D6:D8) -> 2772.18 | E14: =D14-C14 -> 22.18 | F14: =IF(C14<>0,(D14-C14)/C14,0) -> 0.0080654545
A15: Total Cost | C15: =SUM(C9:C13) -> 1985 | D15: =SUM(D9:D13) -> 2109.9 | E15: =D15-C15 -> 124.9 | F15: =IF(C15<>0,(D15-C15)/C15,0) -> 0.062921914
A16: Net P&L (Budget) | C16: =C14-C15 -> 765 | D16: =D14-D15 -> 662.28
A18: SECTION 2: SCENARIO INPUTS
A19: Input Parameter | B19: Value | C19: Meaning
A20: Revenue Stress % | B20: -0.05 | C20: Reduce total FY24 budgeted revenue by this %. Simulates demand shortfall or market loss.
A21: Cost Overrun % | B21: 0.06 | C21: Increase total FY24 budgeted costs by this %. Simulates input inflation or budget breach.
A22: Change the yellow cells above. All stressed figures in Section 3 update automatically.
A24: SECTION 3: STRESSED P&L
A25: Line Item | B25: Category | C25: Base Budget (₹ L) | D25: Stressed Revenue/Cost (₹ L) | E25: Stress Impact (₹ L)
A26: Product A | B26: Revenue | C26: =C6 -> 1380 | D26: =C26*(1+$B$20) -> 1311 | E26: =D26-C26 -> -69
A27: Product B | B27: Revenue | C27: =C7 -> 770 | D27: =C27*(1+$B$20) -> 731.5 | E27: =D27-C27 -> -38.5
A28: Services | B28: Revenue | C28: =C8 -> 600 | D28: =C28*(1+$B$20) -> 570 | E28: =D28-C28 -> -30
A29: Operations | B29: Cost | C29: =C9 -> 1210 | D29: =C29*(1+$B$21) -> 1282.6 | E29: =D29-C29 -> 72.6
A30: Sales | B30: Cost | C30: =C10 -> 275 | D30: =C30*(1+$B$21) -> 291.5 | E30: =D30-C30 -> 16.5
A31: Marketing | B31: Cost | C31: =C11 -> 225 | D31: =C31*(1+$B$21) -> 238.5 | E31: =D31-C31 -> 13.5
A32: HR | B32: Cost | C32: =C12 -> 165 | D32: =C32*(1+$B$21) -> 174.9 | E32: =D32-C32 -> 9.9
A33: Finance & Admin | B33: Cost | C33: =C13 -> 110 | D33: =C33*(1+$B$21) -> 116.6 | E33: =D33-C33 -> 6.6
A34: Stressed Total Revenue | C34: =SUM(C26:C28) -> 2750 | D34: =SUM(D26:D28) -> 2612.5 | E34: =D34-C34 -> -137.5
A35: Stressed Total Cost | C35: =SUM(C29:C33) -> 1985 | D35: =SUM(D29:D33) -> 2104.1 | E35: =D35-C35 -> 119.1
A36: Stressed Net P&L | C36: =C34-C35 -> 765 | D36: =D34-D35 -> 508.4 | E36: =D36-C36 -> -256.6
A37: P&L Impact as % of Base Budget P&L | E37: =IF(C36<>0,E36/C36,0) -> -0.33542484
A39: SECTION 4: NAMED SCENARIO COMPARISON
A40: Metric | B40: Base Case | C40: Moderate Stress | D40: Severe Stress
A41: Revenue Stress % | B41: 0 | C41: -0.05 | D41: -0.12
A42: Cost Overrun % | B42: 0 | C42: 0.03 | D42: 0.08
A43: Stressed Revenue (₹ L) | B43: 2750 | C43: 2612.5 | D43: 2420
...

Sheet Dashboard
A1: MidCore Industries Pvt Ltd — Executive Variance Dashboard (FY2023–FY2024)
A2: Budget vs Actual Analysis | Stress Test Summary | Management Actions | Unit: ₹ Lakhs | Q2: Line Item | R2: Budget Reqired (₹ L) | S2: Actual Budget (₹ L)
A3: This sheet will contain: KPI tiles | Variance waterfall chart | RAG summary | Management action flags | Q3: Product A | R3: =SUMPRODUCT((Raw_Export_Clean!$B$4:$B$195="FY24")*(Raw_Export_Clean!$E$4:$E$195="Product A")*Raw_Export_Clean!$F$4:$F$195) -> 1380 | S3: =SUMPRODUCT((Raw_Export_Clean!$B$4:$B$195="FY24")*(Raw_Export_Clean!$E$4:$E$195="Product A")*Raw_Export_Clean!$G$4:$G$195) -> 1436.59
A4: FY24 BUDGETED NET P&L | C4: FY24 ACTUAL NET P&L | F4: PRODUCT B VARIANCE | H4: SEVERE STRESS NET P&L | Q4: Product B | R4: =SUMPRODUCT((Raw_Export_Clean!$B$4:$B$195="FY24")*(Raw_Export_Clean!$E$4:$E$195="Product B")*Raw_Export_Clean!$F$4:$F$195) -> 770 | S4: =SUMPRODUCT((Raw_Export_Clean!$B$4:$B$195="FY24")*(Raw_Export_Clean!$E$4:$E$195="Product B")*Raw_Export_Clean!$G$4:$G$195) -> 667.43
A5: ='Scenario Analysis'!C16 -> 765 | C5: ='Scenario Analysis'!D16 -> 662.28 | F5: =SUMPRODUCT((Raw_Export_Clean!$B$4:$B$195="FY24")*(Raw_Export_Clean!$E$4:$E$195="Product B")*(Raw_Export_Clean!$G$4:$G$195-Raw_Export_Clean!$F$4:$F$195)) -> -102.57 | H5: =315.9 -> 315.9 | Q5: Services | R5: =SUMPRODUCT((Raw_Export_Clean!$B$4:$B$195="FY24")*(Raw_Export_Clean!$E$4:$E$195="Services")*Raw_Export_Clean!$F$4:$F$195) -> 600 | S5: =SUMPRODUCT((Raw_Export_Clean!$B$4:$B$195="FY24")*(Raw_Export_Clean!$E$4:$E$195="Services")*Raw_Export_Clean!$G$4:$G$195) -> 668.16
Q6: Operations | R6: =SUMPRODUCT((Raw_Export_Clean!$B$4:$B$195="FY24")*(Raw_Export_Clean!$E$4:$E$195="Operations")*Raw_Export_Clean!$F$4:$F$195) -> 1210 | S6: =SUMPRODUCT((Raw_Export_Clean!$B$4:$B$195="FY24")*(Raw_Export_Clean!$E$4:$E$195="Operations")*Raw_Export_Clean!$G$4:$G$195) -> 1300.03
A7: ₹ Lakhs | FY24 Plan | C7: ₹ Lakhs | FY24 Performance | F7: ₹ Lakhs | Total FY24 Underperformance | H7: ₹ Lakhs | At -12% Rev, +8% Cost | Q7: Sales | R7: =SUMPRODUCT((Raw_Export_Clean!$B$4:$B$195="FY24")*(Raw_Export_Clean!$E$4:$E$195="Sales")*Raw_Export_Clean!$F$4:$F$195) -> 275 | S7: =SUMPRODUCT((Raw_Export_Clean!$B$4:$B$195="FY24")*(Raw_Export_Clean!$E$4:$E$195="Sales")*Raw_Export_Clean!$G$4:$G$195) -> 278.07
Q8: Marketing | R8: =SUMPRODUCT((Raw_Export_Clean!$B$4:$B$195="FY24")*(Raw_Export_Clean!$E$4:$E$195="Marketing")*Raw_Export_Clean!$F$4:$F$195) -> 225 | S8: =SUMPRODUCT((Raw_Export_Clean!$B$4:$B$195="FY24")*(Raw_Export_Clean!$E$4:$E$195="Marketing")*Raw_Export_Clean!$G$4:$G$195) -> 248.25
Q9: HR | R9: =SUMPRODUCT((Raw_Export_Clean!$B$4:$B$195="FY24")*(Raw_Export_Clean!$E$4:$E$195="HR")*Raw_Export_Clean!$F$4:$F$195) -> 165 | S9: =SUMPRODUCT((Raw_Export_Clean!$B$4:$B$195="FY24")*(Raw_Export_Clean!$E$4:$E$195="HR")*Raw_Export_Clean!$G$4:$G$195) -> 172.41
Q10: Finance & Admin | R10: =SUMPRODUCT((Raw_Export_Clean!$B$4:$B$195="FY24")*(Raw_Export_Clean!$E$4:$E$195="Finance & Admin")*Raw_Export_Clean!$F$4:$F$195) -> 110 | S10: =SUMPRODUCT((Raw_Export_Clean!$B$4:$B$195="FY24")*(Raw_Export_Clean!$E$4:$E$195="Finance & Admin")*Raw_Export_Clean!$G$4:$G$195) -> 111.14
Q15: Month | R15: Budget Reqired (₹ L) | S15: Actual Budget (₹ L)
Q16: Apr-23 | R16: =SUMPRODUCT((Raw_Export_Clean!$A$4:$A$195="Apr-23")*(Raw_Export_Clean!$D$4:$D$195="Revenue")*Raw_Export_Clean!$F$4:$F$195) -> 192.5 | S16: =SUMPRODUCT((Raw_Export_Clean!$A$4:$A$195="Apr-23")*(Raw_Export_Clean!$D$4:$D$195="Revenue")*Raw_Export_Clean!$G$4:$G$195) -> 193.37
Q17: May-23 | R17: =SUMPRODUCT((Raw_Export_Clean!$A$4:$A$195="May-23")*(Raw_Export_Clean!$D$4:$D$195="Revenue")*Raw_Export_Clean!$F$4:$F$195) -> 192.5 | S17: =SUMPRODUCT((Raw_Export_Clean!$A$4:$A$195="May-23")*(Raw_Export_Clean!$D$4:$D$195="Revenue")*Raw_Export_Clean!$G$4:$G$195) -> 192.28
Q18: Jun-23 | R18: =SUMPRODUCT((Raw_Export_Clean!$A$4:$A$195="Jun-23")*(Raw_Export_Clean!$D$4:$D$195="Revenue")*Raw_Export_Clean!$F$4:$F$195) -> 192.5 | S18: =SUMPRODUCT((Raw_Export_Clean!$A$4:$A$195="Jun-23")*(Raw_Export_Clean!$D$4:$D$195="Revenue")*Raw_Export_Clean!$G$4:$G$195) -> 194.09
Q19: Jul-23 | R19: =SUMPRODUCT((Raw_Export_Clean!$A$4:$A$195="Jul-23")*(Raw_Export_Clean!$D$4:$D$195="Revenue")*Raw_Export_Clean!$F$4:$F$195) -> 220 | S19: =SUMPRODUCT((Raw_Export_Clean!$A$4:$A$195="Jul-23")*(Raw_Export_Clean!$D$4:$D$195="Revenue")*Raw_Export_Clean!$G$4:$G$195) -> 221.81
Q20: Aug-23 | R20: =SUMPRODUCT((Raw_Export_Clean!$A$4:$A$195="Aug-23")*(Raw_Export_Clean!$D$4:$D$195="Revenue")*Raw_Export_Clean!$F$4:$F$195) -> 220 | S20: =SUMPRODUCT((Raw_Export_Clean!$A$4:$A$195="Aug-23")*(Raw_Export_Clean!$D$4:$D$195="Revenue")*Raw_Export_Clean!$G$4:$G$195) -> 219
Q21: Sep-23 | R21: =SUMPRODUCT((Raw_Export_Clean!$A$4:$A$195="Sep-23")*(Raw_Export_Clean!$D$4:$D$195="Revenue")*Raw_Export_Clean!$F$4:$F$195) -> 220 | S21: =SUMPRODUCT((Raw_Export_Clean!$A$4:$A$195="Sep-23")*(Raw_Export_Clean!$D$4:$D$195="Revenue")*Raw_Export_Clean!$G$4:$G$195) -> 222.79
Q22: Oct-23 | R22: =SUMPRODUCT((Raw_Export_Clean!$A$4:$A$195="Oct-23")*(Raw_Export_Clean!$D$4:$D$195="Revenue")*Raw_Export_Clean!$F$4:$F$195) -> 275 | S22: =SUMPRODUCT((Raw_Export_Clean!$A$4:$A$195="Oct-23")*(Raw_Export_Clean!$D$4:$D$195="Revenue")*Raw_Export_Clean!$G$4:$G$195) -> 278.92
Q23: Nov-23 | R23: =SUMPRODUCT((Raw_Export_Clean!$A$4:$A$195="Nov-23")*(Raw_Export_Clean!$D$4:$D$195="Revenue")*Raw_Export_Clean!$F$4:$F$195) -> 302.5 | S23: =SUMPRODUCT((Raw_Export_Clean!$A$4:$A$195="Nov-23")*(Raw_Export_Clean!$D$4:$D$195="Revenue")*Raw_Export_Clean!$G$4:$G$195) -> 308.52
Q24: Dec-23 | R24: =SUMPRODUCT((Raw_Export_Clean!$A$4:$A$195="Dec-23")*(Raw_Export_Clean!$D$4:$D$195="Revenue")*Raw_Export_Clean!$F$4:$F$195) -> 275 | S24: =SUMPRODUCT((Raw_Export_Clean!$A$4:$A$195="Dec-23")*(Raw_Export_Clean!$D$4:$D$195="Revenue")*Raw_Export_Clean!$G$4:$G$195) -> 275.57
Q25: Jan-24 | R25: =SUMPRODUCT((Raw_Export_Clean!$A$4:$A$195="Jan-24")*(Raw_Export_Clean!$D$4:$D$195="Revenue")*Raw_Export_Clean!$F$4:$F$195) -> 247.5 | S25: =SUMPRODUCT((Raw_Export_Clean!$A$4:$A$195="Jan-24")*(Raw_Export_Clean!$D$4:$D$195="Revenue")*Raw_Export_Clean!$G$4:$G$195) -> 251.03
Q26: Feb-24 | R26: =SUMPRODUCT((Raw_Export_Clean!$A$4:$A$195="Feb-24")*(Raw_Export_Clean!$D$4:$D$195="Revenue")*Raw_Export_Clean!$F$4:$F$195) -> 220 | S26: =SUMPRODUCT((Raw_Export_Clean!$A$4:$A$195="Feb-24")*(Raw_Export_Clean!$D$4:$D$195="Revenue")*Raw_Export_Clean!$G$4:$G$195) -> 220.32
Q27: Mar-24 | R27: =SUMPRODUCT((Raw_Export_Clean!$A$4:$A$195="Mar-24")*(Raw_Export_Clean!$D$4:$D$195="Revenue")*Raw_Export_Clean!$F$4:$F$195) -> 192.5 | S27: =SUMPRODUCT((Raw_Export_Clean!$A$4:$A$195="Mar-24")*(Raw_Export_Clean!$D$4:$D$195="Revenue")*Raw_Export_Clean!$G$4:$G$195) -> 194.48
A33: RAG PERFORMANCE SUMMARY — FY24
A34: Line Item | B34: Category | C34: FY24 Budget (₹L) | D34: FY24 Actual (₹L) | E34: Variance (₹L) | F34: Variance % | G34: Status | H34: Management Signal
A35: Product A | B35: Revenue | C35: =SUMPRODUCT((Raw_Export_Clean!$B$4:$B$195="FY24")*(Raw_Export_Clean!$E$4:$E$195="Product A")*Raw_Export_Clean!$F$4:$F$195) -> 1380 | D35: =SUMPRODUCT((Raw_Export_Clean!$B$4:$B$195="FY24")*(Raw_Export_Clean!$E$4:$E$195="Product A")*Raw_Export_Clean!$G$4:$G$195) -> 1436.59 | E35: =D35-C35 -> 56.59 | F35: =IF(C35<>0,(D35-C35)/C35,0) -> 0.041007246 | G35: GREEN | H35: GROW — consistently above budget. Increase allocation in FY25 plan.
A36: Product B | B36: Revenue | C36: =SUMPRODUCT((Raw_Export_Clean!$B$4:$B$195="FY24")*(Raw_Export_Clean!$E$4:$E$195="Product B")*Raw_Export_Clean!$F$4:$F$195) -> 770 | D36: =SUMPRODUCT((Raw_Export_Clean!$B$4:$B$195="FY24")*(Raw_Export_Clean!$E$4:$E$195="Product B")*Raw_Export_Clean!$G$4:$G$195) -> 667.43 | E36: =D36-C36 -> -102.57 | F36: =IF(C36<>0,(D36-C36)/C36,0) -> -0.13320779 | G36: RED | H36: EXIT REVIEW — persistent underperformance. Initiate product review.
A37: Services | B37: Revenue | C37: =SUMPRODUCT((Raw_Export_Clean!$B$4:$B$195="FY24")*(Raw_Export_Clean!$E$4:$E$195="Services")*Raw_Export_Clean!$F$4:$F$195) -> 600 | D37: =SUMPRODUCT((Raw_Export_Clean!$B$4:$B$195="FY24")*(Raw_Export_Clean!$E$4:$E$195="Services")*Raw_Export_Clean!$G$4:$G$195) -> 668.16 | E37: =D37-C37 -> 68.16 | F37: =IF(C37<>0,(D37-C37)/C37,0) -> 0.1136 | G37: GREEN | H37: GROW — above budget every month. Prioritise capacity expansion.
A38: Operations | B38: Cost | C38: =SUMPRODUCT((Raw_Export_Clean!$B$4:$B$195="FY24")*(Raw_Export_Clean!$E$4:$E$195="Operations")*Raw_Export_Clean!$F$4:$F$195) -> 1210 | D38: =SUMPRODUCT((Raw_Export_Clean!$B$4:$B$195="FY24")*(Raw_Export_Clean!$E$4:$E$195="Operations")*Raw_Export_Clean!$G$4:$G$195) -> 1300.03 | E38: =D38-C38 -> 90.03 | F38: =IF(C38<>0,(D38-C38)/C38,0) -> 0.074404959 | G38: RED | H38: CONTROL — cost inflation accelerating in FY24. Procurement audit needed.
A39: Sales | B39: Cost | C39: =SUMPRODUCT((Raw_Export_Clean!$B$4:$B$195="FY24")*(Raw_Export_Clean!$E$4:$E$195="Sales")*Raw_Export_Clean!$F$4:$F$195) -> 275 | D39: =SUMPRODUCT((Raw_Export_Clean!$B$4:$B$195="FY24")*(Raw_Export_Clean!$E$4:$E$195="Sales")*Raw_Export_Clean!$G$4:$G$195) -> 278.07 | E39: =D39-C39 -> 3.07 | F39: =IF(C39<>0,(D39-C39)/C39,0) -> 0.011163636 | G39: AMBER | H39: HOLD — near budget. Monitor incentive structure vs revenue output.
A40: Marketing | B40: Cost | C40: =SUMPRODUCT((Raw_Export_Clean!$B$4:$B$195="FY24")*(Raw_Export_Clean!$E$4:$E$195="Marketing")*Raw_Export_Clean!$F$4:$F$195) -> 225 | D40: =SUMPRODUCT((Raw_Export_Clean!$B$4:$B$195="FY24")*(Raw_Export_Clean!$E$4:$E$195="Marketing")*Raw_Export_Clean!$G$4:$G$195) -> 248.25 | E40: =D40-C40 -> 23.25 | F40: =IF(C40<>0,(D40-C40)/C40,0) -> 0.10333333 | G40: RED | H40: REVIEW — significant FY24 overrun. Demand ROI accountability.
A41: HR | B41: Cost | C41: =SUMPRODUCT((Raw_Export_Clean!$B$4:$B$195="FY24")*(Raw_Export_Clean!$E$4:$E$195="HR")*Raw_Export_Clean!$F$4:$F$195) -> 165 | D41: =SUMPRODUCT((Raw_Export_Clean!$B$4:$B$195="FY24")*(Raw_Export_Clean!$E$4:$E$195="HR")*Raw_Export_Clean!$G$4:$G$195) -> 172.41 | E41: =D41-C41 -> 7.41 | F41: =IF(C41<>0,(D41-C41)/C41,0) -> 0.044909091 | G41: AMBER | H41: WATCH — attrition costs rising. Retention intervention in Q3 FY25.
A42: Finance & Admin | B42: Cost | C42: =SUMPRODUCT((Raw_Export_Clean!$B$4:$B$195="FY24")*(Raw_Export_Clean!$E$4:$E$195="Finance & Admin")*Raw_Export_Clean!$F$4:$F$195) -> 110 | D42: =SUMPRODUCT((Raw_Export_Clean!$B$4:$B$195="FY24")*(Raw_Export_Clean!$E$4:$E$195="Finance & Admin")*Raw_Export_Clean!$G$4:$G$195) -> 111.14 | E42: =D42-C42 -> 1.14 | F42: =IF(C42<>0,(D42-C42)/C42,0) -> 0.010363636 | G42: GREEN | H42: HOLD — tightly controlled. No action required.
A43: KEY FINDING: Product B is in structural decline (-13% avg FY24). Operations cost inflation is accelerating (+7% avg FY24). Together these two lines account for 80%+ of total adverse variance. CFO action: freeze Product B budgeted growth in FY25 and initiate procurement review for Operations by Q1 FY25.
